Workbook

Sheet Model Information
A1: Foresight Generated EPI Model
A3: Field | B3: Value
A4: Model name | B4: Atopic Dermatitis - Product X
A5: Disease / indication | B5: Atopic Dermatitis
A6: Country | B6: United States
A7: Start year | B7: 2026
A8: End year | B8: 2040
A9: Horizon | B9: 15
A10: Generated | B10: 2026-07-24T08:06:49.079Z
A11: Generation method | B11: Browser-based static Excel generator
A12: Governance | B12: Draft model; review and approve assumptions before use

Sheet Model Architecture
A1: Stage | B1: Configured structure
A2: Model family | B2: Epidemiology-Based Forecast
A3: Disease / indication | B3: Atopic Dermatitis
A4: Country | B4: United States
A5: Forecast period | B5: 2026-2040
A6: Patient pool entry | B6: Prevalence Pool
A7: Epidemiology basis | B7: Prevalence
A8: Age groups | B8: 3 groups: Adolescents, Adults, Older adults
A9: Diagnosis | B9: 1 segment(s), 0 subsegment(s)
A10: Treatment | B10: 1 segment(s), 0 subsegment(s)
A11: Line of therapy | B11: Not included
A12: Product classes | B12: 3 class(es)
A13: Products | B13: 4 marketed + 1 pipeline per class

Sheet Input Register
A1: Category | B1: Model stage | C1: Input / assumption | D1: Unit | E1: Source / note
A2: Population | B2: Population | C2: Adolescents | E2: Population / share input
A3: Population | B3: Population | C3: Adults | E3: Population / share input
A4: Population | B4: Population | C4: Older adults | E4: Population / share input
A5: Epidemiology | B5: Prevalence Pool | C5: Prevalence input | E5: Rate or patient count
A6: Diagnosis | B6: Diagnosis | C6: Diagnosis Segment 1 | E6: Segment input
A7: Treatment | B7: Treatment | C7: Treatment Segment 1 | E7: Segment input
A8: Class | B8: Treatment Segment 1 | C8: Treatment Segment 1 / Class 1 | E8: Class input
A9: Product | B9: Treatment Segment 1 / Class 1 | C9: Treatment Segment 1 / Class 1 / Marketed Product 1 | E9: Product input
A10: Product | B10: Treatment Segment 1 / Class 1 | C10: Treatment Segment 1 / Class 1 / Marketed Product 2 | E10: Product input
A11: Product | B11: Treatment Segment 1 / Class 1 | C11: Treatment Segment 1 / Class 1 / Marketed Product 3 | E11: Product input
A12: Product | B12: Treatment Segment 1 / Class 1 | C12: Treatment Segment 1 / Class 1 / Marketed Product 4 | E12: Product input
A13: Product | B13: Treatment Segment 1 / Class 1 | C13: Treatment Segment 1 / Class 1 / Pipeline Product 1 | E13: Product input
... A25: Product | B25: Treatment Segment 1 / Class 3 | C25: Treatment Segment 1 / Class 3 / Pipeline Product 1 | E25: Product input

Sheet Assumptions
A1: Assumption | B1: Unit | C1: Base | D1: Strong | E1: Weak | F1: Guidance
A2: Starting population | B2: patients | C2: 1000000 | D2: 1000000 | E2: 1000000 | F2: Replace with country population or entry pool
A3: Annual population growth | B3: % | C3: 0.005 | D3: 0.007 | E3: 0.003 | F3: Annual growth rate
A4: Prevalence rate | B4: % | C4: 0.05 | D4: 0.052 | E4: 0.048 | F4: Use only for prevalence-pool models
A5: Diagnosis rate — start | B5: % | C5: 0.6 | D5: 0.62 | E5: 0.57 | F5: Diagnosed / prevalent
A6: Diagnosis rate — end | B6: % | C6: 0.65 | D6: 0.7 | E6: 0.6 | F6: End-of-horizon diagnosis rate
A7: Treatment rate | B7: % | C7: 0.8 | D7: 0.84 | E7: 0.75 | F7: Treated / diagnosed
A8: Clinical eligibility | B8: % | C8: 0.6 | D8: 0.65 | E8: 0.55 | F8: Eligible / treated
A9: Launch year | B9: year | C9: 2027 | D9: 2027 | E9: 2028 | F9: First year with product share
A10: Peak product share | B10: % | C10: 0.2 | D10: 0.25 | E10: 0.15 | F10: Peak share of eligible patients
A11: Years to peak | B11: years | C11: 5 | D11: 4 | E11: 7 | F11: Linear demonstration ramp
A12: Annual doses per patient | B12: doses | C12: 365 | D12: 365 | E12: 365 | F12: Replace with dosing logic
A13: Adherence | B13: % | C13: 0.75 | D13: 0.8 | E13: 0.68 | F13: Applied to product volume
... A16: Gross-to-net discount | B16: % | C16: 0.18 | D16: 0.16 | E16: 0.23 | F16: Applied to gross revenue

Sheet Forecast Outputs
A1: Base Scenario
A2: Metric | B2: Unit | C2: 2026 | D2: 2027 | E2: 2028 | F2: 2029 | G2: 2030 | H2: 2031 | I2: 2032 | J2: 2033 | K2: 2034 | L2: 2035 | M2: 2036 | N2: 2037 | O2: 2038 | P2: 2039 | Q2: 2040
A3: Population | B3: patients | C3: =Assumptions!$C$2 -> 0 | D3: =B3*(1+Assumptions!$C$3) -> 0 | E3: =C3*(1+Assumptions!$C$3) -> 0 | F3: =D3*(1+Assumptions!$C$3) -> 0 | G3: =E3*(1+Assumptions!$C$3) -> 0 | H3: =F3*(1+Assumptions!$C$3) -> 0 | I3: =G3*(1+Assumptions!$C$3) -> 0 | J3: =H3*(1+Assumptions!$C$3) -> 0 | K3: =I3*(1+Assumptions!$C$3) -> 0 | ... Q3: =O3*(1+Assumptions!$C$3) -> 0
A4: Prevalence rate | B4: % | C4: =Assumptions!$C$4 -> 0 | D4: =Assumptions!$C$4 -> 0 | E4: =Assumptions!$C$4 -> 0 | F4: =Assumptions!$C$4 -> 0 | G4: =Assumptions!$C$4 -> 0 | H4: =Assumptions!$C$4 -> 0 | I4: =Assumptions!$C$4 -> 0 | J4: =Assumptions!$C$4 -> 0 | ... Q4: =Assumptions!$C$4 -> 0
A5: Prevalent patients | B5: patients | C5: =C3*C4 -> 0 | D5: =D3*D4 -> 0 | E5: =E3*E4 -> 0 | F5: =F3*F4 -> 0 | G5: =G3*G4 -> 0 | H5: =H3*H4 -> 0 | I5: =I3*I4 -> 0 | J5: =J3*J4 -> 0 | ... Q5: =Q3*Q4 -> 0
A6: Diagnosis rate | B6: % | C6: =Assumptions!$C$5+(Assumptions!$C$6-Assumptions!$C$5)*0/14 -> 0 | D6: =Assumptions!$C$5+(Assumptions!$C$6-Assumptions!$C$5)*1/14 -> 0 | E6: =Assumptions!$C$5+(Assumptions!$C$6-Assumptions!$C$5)*2/14 -> 0 | F6: =Assumptions!$C$5+(Assumptions!$C$6-Assumptions!$C$5)*3/14 -> 0 | G6: =Assumptions!$C$5+(Assumptions!$C$6-Assumptions!$C$5)*4/14 -> 0 | H6: =Assumptions!$C$5+(Assumptions!$C$6-Assumptions!$C$5)*5/14 -> 0 | I6: =Assumptions!$C$5+(Assumptions!$C$6-Assumptions!$C$5)*6/14 -> 0 | J6: =Assumptions!$C$5+(Assumptions!$C$6-Assumptions!$C$5)*7/14 -> 0 | K6: =Assumptions!$C$5+(Assumptions!$C$6-Assumptions!$C$5)*8/14 -> 0 | L6: =Assumptions!$C$5+(Assumptions!$C$6-Assumptions!$C$5)*9/14 -> 0 | M6: =Assumptions!$C$5+(Assumptions!$C$6-Assumptions!$C$5)*10/14 -> 0 | N6: =Assumptions!$C$5+(Assumptions!$C$6-Assumptions!$C$5)*11/14 -> 0 | O6: =Assumptions!$C$5+(Assumptions!$C$6-Assumptions!$C$5)*12/14 -> 0 | P6: =Assumptions!$C$5+(Assumptions!$C$6-Assumptions!$C$5)*13/14 -> 0 | Q6: =Assumptions!$C$5+(Assumptions!$C$6-Assumptions!$C$5)*14/14 -> 0
A7: Diagnosed patients | B7: patients | C7: =C5*C6 -> 0 | D7: =D5*D6 -> 0 | E7: =E5*E6 -> 0 | F7: =F5*F6 -> 0 | G7: =G5*G6 -> 0 | H7: =H5*H6 -> 0 | I7: =I5*I6 -> 0 | J7: =J5*J6 -> 0 | ... Q7: =Q5*Q6 -> 0
A8: Treatment rate | B8: % | C8: =Assumptions!$C$7 -> 0 | D8: =Assumptions!$C$7 -> 0 | E8: =Assumptions!$C$7 -> 0 | F8: =Assumptions!$C$7 -> 0 | G8: =Assumptions!$C$7 -> 0 | H8: =Assumptions!$C$7 -> 0 | I8: =Assumptions!$C$7 -> 0 | J8: =Assumptions!$C$7 -> 0 | ... Q8: =Assumptions!$C$7 -> 0
A9: Treated patients | B9: patients | C9: =C7*C8 -> 0 | D9: =D7*D8 -> 0 | E9: =E7*E8 -> 0 | F9: =F7*F8 -> 0 | G9: =G7*G8 -> 0 | H9: =H7*H8 -> 0 | I9: =I7*I8 -> 0 | J9: =J7*J8 -> 0 | ... Q9: =Q7*Q8 -> 0
A10: Clinical eligibility | B10: % | C10: =Assumptions!$C$8 -> 0 | D10: =Assumptions!$C$8 -> 0 | E10: =Assumptions!$C$8 -> 0 | F10: =Assumptions!$C$8 -> 0 | G10: =Assumptions!$C$8 -> 0 | H10: =Assumptions!$C$8 -> 0 | I10: =Assumptions!$C$8 -> 0 | J10: =Assumptions!$C$8 -> 0 | ... Q10: =Assumptions!$C$8 -> 0
A11: Eligible patients | B11: patients | C11: =C9*C10 -> 0 | D11: =D9*D10 -> 0 | E11: =E9*E10 -> 0 | F11: =F9*F10 -> 0 | G11: =G9*G10 -> 0 | H11: =H9*H10 -> 0 | I11: =I9*I10 -> 0 | J11: =J9*J10 -> 0 | ... Q11: =Q9*Q10 -> 0
A12: Product share | B12: % | C12: =IF(2026<Assumptions!$C$9,0,MIN(Assumptions!$C$10,(2026-Assumptions!$C$9+1)/Assumptions!$C$11*Assumptions!$C$10)) -> 0 | D12: =IF(2027<Assumptions!$C$9,0,MIN(Assumptions!$C$10,(2027-Assumptions!$C$9+1)/Assumptions!$C$11*Assumptions!$C$10)) -> 0 | E12: =IF(2028<Assumptions!$C$9,0,MIN(Assumptions!$C$10,(2028-Assumptions!$C$9+1)/Assumptions!$C$11*Assumptions!$C$10)) -> 0 | F12: =IF(2029<Assumptions!$C$9,0,MIN(Assumptions!$C$10,(2029-Assumptions!$C$9+1)/Assumptions!$C$11*Assumptions!$C$10)) -> 0 | G12: =IF(2030<Assumptions!$C$9,0,MIN(Assumptions!$C$10,(2030-Assumptions!$C$9+1)/Assumptions!$C$11*Assumptions!$C$10)) -> 0 | H12: =IF(2031<Assumptions!$C$9,0,MIN(Assumptions!$C$10,(2031-Assumptions!$C$9+1)/Assumptions!$C$11*Assumptions!$C$10)) -> 0 | I12: =IF(2032<Assumptions!$C$9,0,MIN(Assumptions!$C$10,(2032-Assumptions!$C$9+1)/Assumptions!$C$11*Assumptions!$C$10)) -> 0 | J12: =IF(2033<Assumptions!$C$9,0,MIN(Assumptions!$C$10,(2033-Assumptions!$C$9+1)/Assumptions!$C$11*Assumptions!$C$10)) -> 0 | K12: =IF(2034<Assumptions!$C$9,0,MIN(Assumptions!$C$10,(2034-Assumptions!$C$9+1)/Assumptions!$C$11*Assumptions!$C$10)) -> 0 | L12: =IF(2035<Assumptions!$C$9,0,MIN(Assumptions!$C$10,(2035-Assumptions!$C$9+1)/Assumptions!$C$11*Assumptions!$C$10)) -> 0 | M12: =IF(2036<Assumptions!$C$9,0,MIN(Assumptions!$C$10,(2036-Assumptions!$C$9+1)/Assumptions!$C$11*Assumptions!$C$10)) -> 0 | N12: =IF(2037<Assumptions!$C$9,0,MIN(Assumptions!$C$10,(2037-Assumptions!$C$9+1)/Assumptions!$C$11*Assumptions!$C$10)) -> 0 | O12: =IF(2038<Assumptions!$C$9,0,MIN(Assumptions!$C$10,(2038-Assumptions!$C$9+1)/Assumptions!$C$11*Assumptions!$C$10)) -> 0 | P12: =IF(2039<Assumptions!$C$9,0,MIN(Assumptions!$C$10,(2039-Assumptions!$C$9+1)/Assumptions!$C$11*Assumptions!$C$10)) -> 0 | Q12: =IF(2040<Assumptions!$C$9,0,MIN(Assumptions!$C$10,(2040-Assumptions!$C$9+1)/Assumptions!$C$11*Assumptions!$C$10)) -> 0
A13: Product patients | B13: patients | C13: =C11*C12 -> 0 | D13: =D11*D12 -> 0 | E13: =E11*E12 -> 0 | F13: =F11*F12 -> 0 | G13: =G11*G12 -> 0 | H13: =H11*H12 -> 0 | I13: =I11*I12 -> 0 | J13: =J11*J12 -> 0 | ... Q13: =Q11*Q12 -> 0
A14: Annual doses per patient | B14: doses | C14: =Assumptions!$C$12 -> 0 | D14: =Assumptions!$C$12 -> 0 | E14: =Assumptions!$C$12 -> 0 | F14: =Assumptions!$C$12 -> 0 | G14: =Assumptions!$C$12 -> 0 | H14: =Assumptions!$C$12 -> 0 | I14: =Assumptions!$C$12 -> 0 | J14: =Assumptions!$C$12 -> 0 | ... Q14: =Assumptions!$C$12 -> 0
A15: Adherence | B15: % | C15: =Assumptions!$C$13 -> 0 | D15: =Assumptions!$C$13 -> 0 | E15: =Assumptions!$C$13 -> 0 | F15: =Assumptions!$C$13 -> 0 | G15: =Assumptions!$C$13 -> 0 | H15: =Assumptions!$C$13 -> 0 | I15: =Assumptions!$C$13 -> 0 | J15: =Assumptions!$C$13 -> 0 | ... Q15: =Assumptions!$C$13 -> 0
A16: Product volume | B16: doses | C16: =C13*C14*C15 -> 0 | D16: =D13*D14*D15 -> 0 | E16: =E13*E14*E15 -> 0 | F16: =F13*F14*F15 -> 0 | G16: =G13*G14*G15 -> 0 | H16: =H13*H14*H15 -> 0 | I16: =I13*I14*I15 -> 0 | J16: =J13*J14*J15 -> 0 | ... Q16: =Q13*Q14*Q15 -> 0
A17: List price per dose | B17: currency | C17: =Assumptions!$C$14*(1+Assumptions!$C$15)^0 -> 0 | D17: =Assumptions!$C$14*(1+Assumptions!$C$15)^1 -> 0 | E17: =Assumptions!$C$14*(1+Assumptions!$C$15)^2 -> 0 | F17: =Assumptions!$C$14*(1+Assumptions!$C$15)^3 -> 0 | G17: =Assumptions!$C$14*(1+Assumptions!$C$15)^4 -> 0 | H17: =Assumptions!$C$14*(1+Assumptions!$C$15)^5 -> 0 | I17: =Assumptions!$C$14*(1+Assumptions!$C$15)^6 -> 0 | J17: =Assumptions!$C$14*(1+Assumptions!$C$15)^7 -> 0 | K17: =Assumptions!$C$14*(1+Assumptions!$C$15)^8 -> 0 | L17: =Assumptions!$C$14*(1+Assumptions!$C$15)^9 -> 0 | M17: =Assumptions!$C$14*(1+Assumptions!$C$15)^10 -> 0 | N17: =Assumptions!$C$14*(1+Assumptions!$C$15)^11 -> 0 | O17: =Assumptions!$C$14*(1+Assumptions!$C$15)^12 -> 0 | P17: =Assumptions!$C$14*(1+Assumptions!$C$15)^13 -> 0 | Q17: =Assumptions!$C$14*(1+Assumptions!$C$15)^14 -> 0
A18: Gross revenue | B18: currency | C18: =C16*C17 -> 0 | D18: =D16*D17 -> 0 | E18: =E16*E17 -> 0 | F18: =F16*F17 -> 0 | G18: =G16*G17 -> 0 | H18: =H16*H17 -> 0 | I18: =I16*I17 -> 0 | J18: =J16*J17 -> 0 | ... Q18: =Q16*Q17 -> 0
A19: Gross-to-net discount | B19: % | C19: =Assumptions!$C$16 -> 0 | D19: =Assumptions!$C$16 -> 0 | E19: =Assumptions!$C$16 -> 0 | F19: =Assumptions!$C$16 -> 0 | G19: =Assumptions!$C$16 -> 0 | H19: =Assumptions!$C$16 -> 0 | I19: =Assumptions!$C$16 -> 0 | J19: =Assumptions!$C$16 -> 0 | ... Q19: =Assumptions!$C$16 -> 0
A20: Net revenue | B20: currency | C20: =C18*(1-C19) -> 0 | D20: =D18*(1-D19) -> 0 | E20: =E18*(1-E19) -> 0 | F20: =F18*(1-F19) -> 0 | G20: =G18*(1-G19) -> 0 | H20: =H18*(1-H19) -> 0 | I20: =I18*(1-I19) -> 0 | J20: =J18*(1-J19) -> 0 | ... Q20: =Q18*(1-Q19) -> 0
A22: Strong Scenario
A23: Metric | B23: Unit | C23: 2026 | D23: 2027 | E23: 2028 | F23: 2029 | G23: 2030 | H23: 2031 | I23: 2032 | J23: 2033 | K23: 2034 | L23: 2035 | M23: 2036 | N23: 2037 | O23: 2038 | P23: 2039 | Q23: 2040
A24: Population | B24: patients | C24: =Assumptions!$D$2 -> 0 | D24: =B25*(1+Assumptions!$D$3) -> 0 | E24: =C25*(1+Assumptions!$D$3) -> 0 | F24: =D25*(1+Assumptions!$D$3) -> 0 | G24: =E25*(1+Assumptions!$D$3) -> 0 | H24: =F25*(1+Assumptions!$D$3) -> 0 | I24: =G25*(1+Assumptions!$D$3) -> 0 | J24: =H25*(1+Assumptions!$D$3) -> 0 | K24: =I25*(1+Assumptions!$D$3) -> 0 | ... Q24: =O25*(1+Assumptions!$D$3) -> 0
A25: Prevalence rate | B25: % | C25: =Assumptions!$D$4 -> 0 | D25: =Assumptions!$D$4 -> 0 | E25: =Assumptions!$D$4 -> 0 | F25: =Assumptions!$D$4 -> 0 | G25: =Assumptions!$D$4 -> 0 | H25: =Assumptions!$D$4 -> 0 | I25: =Assumptions!$D$4 -> 0 | J25: =Assumptions!$D$4 -> 0 | ... Q25: =Assumptions!$D$4 -> 0
A26: Prevalent patients | B26: patients | C26: =C25*C26 -> 0 | D26: =D25*D26 -> 0 | E26: =E25*E26 -> 0 | F26: =F25*F26 -> 0 | G26: =G25*G26 -> 0 | H26: =H25*H26 -> 0 | I26: =I25*I26 -> 0 | J26: =J25*J26 -> 0 | ... Q26: =Q25*Q26 -> 0
A27: Diagnosis rate | B27: % | C27: =Assumptions!$D$5+(Assumptions!$D$6-Assumptions!$D$5)*0/14 -> 0 | D27: =Assumptions!$D$5+(Assumptions!$D$6-Assumptions!$D$5)*1/14 -> 0 | E27: =Assumptions!$D$5+(Assumptions!$D$6-Assumptions!$D$5)*2/14 -> 0 | F27: =Assumptions!$D$5+(Assumptions!$D$6-Assumptions!$D$5)*3/14 -> 0 | G27: =Assumptions!$D$5+(Assumptions!$D$6-Assumptions!$D$5)*4/14 -> 0 | H27: =Assumptions!$D$5+(Assumptions!$D$6-Assumptions!$D$5)*5/14 -> 0 | I27: =Assumptions!$D$5+(Assumptions!$D$6-Assumptions!$D$5)*6/14 -> 0 | J27: =Assumptions!$D$5+(Assumptions!$D$6-Assumptions!$D$5)*7/14 -> 0 | K27: =Assumptions!$D$5+(Assumptions!$D$6-Assumptions!$D$5)*8/14 -> 0 | L27: =Assumptions!$D$5+(Assumptions!$D$6-Assumptions!$D$5)*9/14 -> 0 | M27: =Assumptions!$D$5+(Assumptions!$D$6-Assumptions!$D$5)*10/14 -> 0 | N27: =Assumptions!$D$5+(Assumptions!$D$6-Assumptions!$D$5)*11/14 -> 0 | O27: =Assumptions!$D$5+(Assumptions!$D$6-Assumptions!$D$5)*12/14 -> 0 | P27: =Assumptions!$D$5+(Assumptions!$D$6-Assumptions!$D$5)*13/14 -> 0 | Q27: =Assumptions!$D$5+(Assumptions!$D$6-Assumptions!$D$5)*14/14 -> 0
A28: Diagnosed patients | B28: patients | C28: =C27*C28 -> 0 | D28: =D27*D28 -> 0 | E28: =E27*E28 -> 0 | F28: =F27*F28 -> 0 | G28: =G27*G28 -> 0 | H28: =H27*H28 -> 0 | I28: =I27*I28 -> 0 | J28: =J27*J28 -> 0 | ... Q28: =Q27*Q28 -> 0
A29: Treatment rate | B29: % | C29: =Assumptions!$D$7 -> 0 | D29: =Assumptions!$D$7 -> 0 | E29: =Assumptions!$D$7 -> 0 | F29: =Assumptions!$D$7 -> 0 | G29: =Assumptions!$D$7 -> 0 | H29: =Assumptions!$D$7 -> 0 | I29: =Assumptions!$D$7 -> 0 | J29: =Assumptions!$D$7 -> 0 | ... Q29: =Assumptions!$D$7 -> 0
A30: Treated patients | B30: patients | C30: =C29*C30 -> 0 | D30: =D29*D30 -> 0 | E30: =E29*E30 -> 0 | F30: =F29*F30 -> 0 | G30: =G29*G30 -> 0 | H30: =H29*H30 -> 0 | I30: =I29*I30 -> 0 | J30: =J29*J30 -> 0 | ... Q30: =Q29*Q30 -> 0
A31: Clinical eligibility | B31: % | C31: =Assumptions!$D$8 -> 0 | D31: =Assumptions!$D$8 -> 0 | E31: =Assumptions!$D$8 -> 0 | F31: =Assumptions!$D$8 -> 0 | G31: =Assumptions!$D$8 -> 0 | H31: =Assumptions!$D$8 -> 0 | I31: =Assumptions!$D$8 -> 0 | J31: =Assumptions!$D$8 -> 0 | ... Q31: =Assumptions!$D$8 -> 0
A32: Eligible patients | B32: patients | C32: =C31*C32 -> 0 | D32: =D31*D32 -> 0 | E32: =E31*E32 -> 0 | F32: =F31*F32 -> 0 | G32: =G31*G32 -> 0 | H32: =H31*H32 -> 0 | I32: =I31*I32 -> 0 | J32: =J31*J32 -> 0 | ... Q32: =Q31*Q32 -> 0
A33: Product share | B33: % | C33: =IF(2026<Assumptions!$D$9,0,MIN(Assumptions!$D$10,(2026-Assumptions!$D$9+1)/Assumptions!$D$11*Assumptions!$D$10)) -> 0 | D33: =IF(2027<Assumptions!$D$9,0,MIN(Assumptions!$D$10,(2027-Assumptions!$D$9+1)/Assumptions!$D$11*Assumptions!$D$10)) -> 0 | E33: =IF(2028<Assumptions!$D$9,0,MIN(Assumptions!$D$10,(2028-Assumptions!$D$9+1)/Assumptions!$D$11*Assumptions!$D$10)) -> 0 | F33: =IF(2029<Assumptions!$D$9,0,MIN(Assumptions!$D$10,(2029-Assumptions!$D$9+1)/Assumptions!$D$11*Assumptions!$D$10)) -> 0 | G33: =IF(2030<Assumptions!$D$9,0,MIN(Assumptions!$D$10,(2030-Assumptions!$D$9+1)/Assumptions!$D$11*Assumptions!$D$10)) -> 0 | H33: =IF(2031<Assumptions!$D$9,0,MIN(Assumptions!$D$10,(2031-Assumptions!$D$9+1)/Assumptions!$D$11*Assumptions!$D$10)) -> 0 | I33: =IF(2032<Assumptions!$D$9,0,MIN(Assumptions!$D$10,(2032-Assumptions!$D$9+1)/Assumptions!$D$11*Assumptions!$D$10)) -> 0 | J33: =IF(2033<Assumptions!$D$9,0,MIN(Assumptions!$D$10,(2033-Assumptions!$D$9+1)/Assumptions!$D$11*Assumptions!$D$10)) -> 0 | K33: =IF(2034<Assumptions!$D$9,0,MIN(Assumptions!$D$10,(2034-Assumptions!$D$9+1)/Assumptions!$D$11*Assumptions!$D$10)) -> 0 | L33: =IF(2035<Assumptions!$D$9,0,MIN(Assumptions!$D$10,(2035-Assumptions!$D$9+1)/Assumptions!$D$11*Assumptions!$D$10)) -> 0 | M33: =IF(2036<Assumptions!$D$9,0,MIN(Assumptions!$D$10,(2036-Assumptions!$D$9+1)/Assumptions!$D$11*Assumptions!$D$10)) -> 0 | N33: =IF(2037<Assumptions!$D$9,0,MIN(Assumptions!$D$10,(2037-Assumptions!$D$9+1)/Assumptions!$D$11*Assumptions!$D$10)) -> 0 | O33: =IF(2038<Assumptions!$D$9,0,MIN(Assumptions!$D$10,(2038-Assumptions!$D$9+1)/Assumptions!$D$11*Assumptions!$D$10)) -> 0 | P33: =IF(2039<Assumptions!$D$9,0,MIN(Assumptions!$D$10,(2039-Assumptions!$D$9+1)/Assumptions!$D$11*Assumptions!$D$10)) -> 0 | Q33: =IF(2040<Assumptions!$D$9,0,MIN(Assumptions!$D$10,(2040-Assumptions!$D$9+1)/Assumptions!$D$11*Assumptions!$D$10)) -> 0
A34: Product patients | B34: patients | C34: =C33*C34 -> 0 | D34: =D33*D34 -> 0 | E34: =E33*E34 -> 0 | F34: =F33*F34 -> 0 | G34: =G33*G34 -> 0 | H34: =H33*H34 -> 0 | I34: =I33*I34 -> 0 | J34: =J33*J34 -> 0 | ... Q34: =Q33*Q34 -> 0
A35: Annual doses per patient | B35: doses | C35: =Assumptions!$D$12 -> 0 | D35: =Assumptions!$D$12 -> 0 | E35: =Assumptions!$D$12 -> 0 | F35: =Assumptions!$D$12 -> 0 | G35: =Assumptions!$D$12 -> 0 | H35: =Assumptions!$D$12 -> 0 | I35: =Assumptions!$D$12 -> 0 | J35: =Assumptions!$D$12 -> 0 | ... Q35: =Assumptions!$D$12 -> 0
A36: Adherence | B36: % | C36: =Assumptions!$D$13 -> 0 | D36: =Assumptions!$D$13 -> 0 | E36: =Assumptions!$D$13 -> 0 | F36: =Assumptions!$D$13 -> 0 | G36: =Assumptions!$D$13 -> 0 | H36: =Assumptions!$D$13 -> 0 | I36: =Assumptions!$D$13 -> 0 | J36: =Assumptions!$D$13 -> 0 | ... Q36: =Assumptions!$D$13 -> 0
A37: Product volume | B37: doses | C37: =C35*C36*C37 -> 0 | D37: =D35*D36*D37 -> 0 | E37: =E35*E36*E37 -> 0 | F37: =F35*F36*F37 -> 0 | G37: =G35*G36*G37 -> 0 | H37: =H35*H36*H37 -> 0 | I37: =I35*I36*I37 -> 0 | J37: =J35*J36*J37 -> 0 | ... Q37: =Q35*Q36*Q37 -> 0
A38: List price per dose | B38: currency | C38: =Assumptions!$D$14*(1+Assumptions!$D$15)^0 -> 0 | D38: =Assumptions!$D$14*(1+Assumptions!$D$15)^1 -> 0 | E38: =Assumptions!$D$14*(1+Assumptions!$D$15)^2 -> 0 | F38: =Assumptions!$D$14*(1+Assumptions!$D$15)^3 -> 0 | G38: =Assumptions!$D$14*(1+Assumptions!$D$15)^4 -> 0 | H38: =Assumptions!$D$14*(1+Assumptions!$D$15)^5 -> 0 | I38: =Assumptions!$D$14*(1+Assumptions!$D$15)^6 -> 0 | J38: =Assumptions!$D$14*(1+Assumptions!$D$15)^7 -> 0 | K38: =Assumptions!$D$14*(1+Assumptions!$D$15)^8 -> 0 | L38: =Assumptions!$D$14*(1+Assumptions!$D$15)^9 -> 0 | M38: =Assumptions!$D$14*(1+Assumptions!$D$15)^10 -> 0 | N38: =Assumptions!$D$14*(1+Assumptions!$D$15)^11 -> 0 | O38: =Assumptions!$D$14*(1+Assumptions!$D$15)^12 -> 0 | P38: =Assumptions!$D$14*(1+Assumptions!$D$15)^13 -> 0 | Q38: =Assumptions!$D$14*(1+Assumptions!$D$15)^14 -> 0
A39: Gross revenue | B39: currency | C39: =C38*C39 -> 0 | D39: =D38*D39 -> 0 | E39: =E38*E39 -> 0 | F39: =F38*F39 -> 0 | G39: =G38*G39 -> 0 | H39: =H38*H39 -> 0 | I39: =I38*I39 -> 0 | J39: =J38*J39 -> 0 | ... Q39: =Q38*Q39 -> 0
A40: Gross-to-net discount | B40: % | C40: =Assumptions!$D$16 -> 0 | D40: =Assumptions!$D$16 -> 0 | E40: =Assumptions!$D$16 -> 0 | F40: =Assumptions!$D$16 -> 0 | G40: =Assumptions!$D$16 -> 0 | H40: =Assumptions!$D$16 -> 0 | I40: =Assumptions!$D$16 -> 0 | J40: =Assumptions!$D$16 -> 0 | ... Q40: =Assumptions!$D$16 -> 0
A41: Net revenue | B41: currency | C41: =C40*(1-C41) -> 0 | D41: =D40*(1-D41) -> 0 | E41: =E40*(1-E41) -> 0 | F41: =F40*(1-F41) -> 0 | G41: =G40*(1-G41) -> 0 | H41: =H40*(1-H41) -> 0 | I41: =I40*(1-I41) -> 0 | J41: =J40*(1-J41) -> 0 | ... Q41: =Q40*(1-Q41) -> 0
...

Sheet Patient Potential Tower
A1: Year | B1: Prevalent | C1: Diagnosed | D1: Treated | E1: Eligible | F1: Product Patients
A2: 2026 | B2: ='Forecast Outputs'!C5 -> 0 | C2: ='Forecast Outputs'!C7 -> 0 | D2: ='Forecast Outputs'!C9 -> 0 | E2: ='Forecast Outputs'!C11 -> 0 | F2: ='Forecast Outputs'!C13 -> 0
A3: 2027 | B3: ='Forecast Outputs'!D5 -> 0 | C3: ='Forecast Outputs'!D7 -> 0 | D3: ='Forecast Outputs'!D9 -> 0 | E3: ='Forecast Outputs'!D11 -> 0 | F3: ='Forecast Outputs'!D13 -> 0
A4: 2028 | B4: ='Forecast Outputs'!E5 -> 0 | C4: ='Forecast Outputs'!E7 -> 0 | D4: ='Forecast Outputs'!E9 -> 0 | E4: ='Forecast Outputs'!E11 -> 0 | F4: ='Forecast Outputs'!E13 -> 0
A5: 2029 | B5: ='Forecast Outputs'!F5 -> 0 | C5: ='Forecast Outputs'!F7 -> 0 | D5: ='Forecast Outputs'!F9 -> 0 | E5: ='Forecast Outputs'!F11 -> 0 | F5: ='Forecast Outputs'!F13 -> 0
A6: 2030 | B6: ='Forecast Outputs'!G5 -> 0 | C6: ='Forecast Outputs'!G7 -> 0 | D6: ='Forecast Outputs'!G9 -> 0 | E6: ='Forecast Outputs'!G11 -> 0 | F6: ='Forecast Outputs'!G13 -> 0
A7: 2031 | B7: ='Forecast Outputs'!H5 -> 0 | C7: ='Forecast Outputs'!H7 -> 0 | D7: ='Forecast Outputs'!H9 -> 0 | E7: ='Forecast Outputs'!H11 -> 0 | F7: ='Forecast Outputs'!H13 -> 0
A8: 2032 | B8: ='Forecast Outputs'!I5 -> 0 | C8: ='Forecast Outputs'!I7 -> 0 | D8: ='Forecast Outputs'!I9 -> 0 | E8: ='Forecast Outputs'!I11 -> 0 | F8: ='Forecast Outputs'!I13 -> 0
A9: 2033 | B9: ='Forecast Outputs'!J5 -> 0 | C9: ='Forecast Outputs'!J7 -> 0 | D9: ='Forecast Outputs'!J9 -> 0 | E9: ='Forecast Outputs'!J11 -> 0 | F9: ='Forecast Outputs'!J13 -> 0
A10: 2034 | B10: ='Forecast Outputs'!K5 -> 0 | C10: ='Forecast Outputs'!K7 -> 0 | D10: ='Forecast Outputs'!K9 -> 0 | E10: ='Forecast Outputs'!K11 -> 0 | F10: ='Forecast Outputs'!K13 -> 0
A11: 2035 | B11: ='Forecast Outputs'!L5 -> 0 | C11: ='Forecast Outputs'!L7 -> 0 | D11: ='Forecast Outputs'!L9 -> 0 | E11: ='Forecast Outputs'!L11 -> 0 | F11: ='Forecast Outputs'!L13 -> 0
A12: 2036 | B12: ='Forecast Outputs'!M5 -> 0 | C12: ='Forecast Outputs'!M7 -> 0 | D12: ='Forecast Outputs'!M9 -> 0 | E12: ='Forecast Outputs'!M11 -> 0 | F12: ='Forecast Outputs'!M13 -> 0
A13: 2037 | B13: ='Forecast Outputs'!N5 -> 0 | C13: ='Forecast Outputs'!N7 -> 0 | D13: ='Forecast Outputs'!N9 -> 0 | E13: ='Forecast Outputs'!N11 -> 0 | F13: ='Forecast Outputs'!N13 -> 0
A14: 2038 | B14: ='Forecast Outputs'!O5 -> 0 | C14: ='Forecast Outputs'!O7 -> 0 | D14: ='Forecast Outputs'!O9 -> 0 | E14: ='Forecast Outputs'!O11 -> 0 | F14: ='Forecast Outputs'!O13 -> 0
A15: 2039 | B15: ='Forecast Outputs'!P5 -> 0 | C15: ='Forecast Outputs'!P7 -> 0 | D15: ='Forecast Outputs'!P9 -> 0 | E15: ='Forecast Outputs'!P11 -> 0 | F15: ='Forecast Outputs'!P13 -> 0
A16: 2040 | B16: ='Forecast Outputs'!Q5 -> 0 | C16: ='Forecast Outputs'!Q7 -> 0 | D16: ='Forecast Outputs'!Q9 -> 0 | E16: ='Forecast Outputs'!Q11 -> 0 | F16: ='Forecast Outputs'!Q13 -> 0

Sheet Validation
A1: Status | B1: Check | C1: Detail
A2: Passed | B2: Model information | C2: Atopic Dermatitis - Product X · United States · 2026-2040
A3: Passed | B3: Patient-pool configuration | C3: Prevalence Pool · Prevalence
A4: Review | B4: Assumption evidence | C4: Replace illustrative assumption defaults with source-linked approved inputs
A5: Review | B5: Scenario assumptions | C5: Strong and Weak defaults are illustrative starting points
A6: Passed | B6: Formula scaffold | C6: Patient-to-volume-to-revenue formulas included
A7: Passed | B7: Base protection | C7: Scenario sheets are separate and do not overwrite approved inputs
